Workbook

Sheet FLC Cầu Giấy
I1: Mã hiệu: SBL.KDBL.QT.BM.01.02 Lần ban hành: 01 Ngày ban hành: 22/03/2018
A2: BẢNG CHÊNH LỆCH HÀNG HÓA KIỂM KÊ
A6: STT | B6: Loại Hàng | C6: Mã sản phẩm | D6: Mã Barcode | E6: Tên sản phẩm | F6: Giá bán lẻ | G6: Số lượng tồn phần mềm | H6: Số lượng tồn thực tế | I6: Chênh lệch | M6: Lý do ST giải trình | N6: Ngày điều chỉnh
I7: Chênh lệch thừa | K7: Chênh lệch thiếu
I8: Số lượng | J8: Trị giá thừa | K8: Số lượng | L8: Trị giá thiếu
A12: Tổng | I12: =SUM(I9:I11) -> 0 | J12: =SUM(J9:J11) -> 0 | K12: =SUM(K9:K11) -> 0 | L12: =SUM(L9:L11) -> 0 | N12: 44756
D14: Vào lúc …….giờ …….. phút, thứ ….. ngày …28…. tháng …01.. Năm 2022….
B15: Quản lý ST | D15: GSKV | F15: Trưởng nhóm kiểm kê | I15: Giám đốc ĐHBL | M15: Trưởng Phòng Kế Toán
B16: (Ký và ghi rõ họ tên) | D16: (Ký và ghi rõ họ tên) | F16: (Ký và ghi rõ họ tên) | I16: (Ký và ghi rõ họ tên) | M16: (Ký và ghi rõ họ tên)

Sheet Móng cái
I1: Mã hiệu: SBL.KDBL.QT.BM.01.02 Lần ban hành: 01 Ngày ban hành: 22/03/2018
A2: BẢNG CHÊNH LỆCH HÀNG HÓA KIỂM KÊ
A6: STT | B6: Loại Hàng | C6: Mã sản phẩm | D6: Mã Barcode | E6: Tên sản phẩm | F6: Giá bán lẻ | G6: Số lượng tồn phần mềm | H6: Số lượng tồn thực tế | I6: Chênh lệch | M6: Lý do ST giải trình | N6: Ngày điều chỉnh
I7: Chênh lệch thừa | K7: Chênh lệch thiếu
I8: Số lượng | J8: Trị giá thừa | K8: Số lượng | L8: Trị giá thiếu
A12: Tổng | I12: =SUM(I9:I11) -> 0 | J12: =SUM(J9:J11) -> 0 | K12: =SUM(K9:K11) -> 0 | L12: =SUM(L9:L11) -> 0 | N12: 44993
D14: Vào lúc …….giờ …….. phút, thứ ….. ngày …28…. tháng …01.. Năm 2022….
B15: Quản lý ST | D15: GSKV | F15: Trưởng nhóm kiểm kê | I15: Giám đốc ĐHBL | M15: Trưởng Phòng Kế Toán
B16: (Ký và ghi rõ họ tên) | D16: (Ký và ghi rõ họ tên) | F16: (Ký và ghi rõ họ tên) | I16: (Ký và ghi rõ họ tên) | M16: (Ký và ghi rõ họ tên)

Sheet Nguyễn Văn Lộc
I1: Mã hiệu: SBL.KDBL.QT.BM.01.02 Lần ban hành: 01 Ngày ban hành: 22/03/2018
A2: BẢNG CHÊNH LỆCH HÀNG HÓA KIỂM KÊ
A6: STT | B6: Loại Hàng | C6: Mã sản phẩm | D6: Mã Barcode | E6: Tên sản phẩm | F6: Giá bán lẻ | G6: Số lượng tồn phần mềm | H6: Số lượng tồn thực tế | I6: Chênh lệch | M6: Lý do ST giải trình | N6: Ngày điều chỉnh
I7: Chênh lệch thừa | K7: Chênh lệch thiếu
I8: Số lượng | J8: Trị giá thừa | K8: Số lượng | L8: Trị giá thiếu
A10: Tổng | I10: =SUM(I9:I9) -> 0 | J10: =SUM(J9:J9) -> 0 | K10: =SUM(K9:K9) -> 0 | L10: =SUM(L9:L9) -> 0 | N10: 44777
D12: Vào lúc …….giờ …….. phút, thứ ….. ngày …28…. tháng …01.. Năm 2022….
B13: Quản lý ST | D13: GSKV | F13: Trưởng nhóm kiểm kê | I13: Giám đốc ĐHBL | M13: Trưởng Phòng Kế Toán
B14: (Ký và ghi rõ họ tên) | D14: (Ký và ghi rõ họ tên) | F14: (Ký và ghi rõ họ tên) | I14: (Ký và ghi rõ họ tên) | M14: (Ký và ghi rõ họ tên)

Sheet oceanpark
I1: Mã hiệu: SBL.KDBL.QT.BM.01.02 Lần ban hành: 01 Ngày ban hành: 22/03/2018
A2: BẢNG CHÊNH LỆCH HÀNG HÓA KIỂM KÊ
A6: STT | B6: Loại Hàng | C6: Mã sản phẩm | D6: Mã Barcode | E6: Tên sản phẩm | F6: Giá bán lẻ | G6: Số lượng tồn phần mềm | H6: Số lượng tồn thực tế | I6: Chênh lệch | M6: Lý do ST giải trình | N6: Ngày điều chỉnh
I7: Chênh lệch thừa | K7: Chênh lệch thiếu
I8: Số lượng | J8: Trị giá thừa | K8: Số lượng | L8: Trị giá thiếu
A10: Tổng | I10: =SUM(I9:I9) -> 0 | J10: =SUM(J9:J9) -> 0 | K10: =SUM(K9:K9) -> 0 | L10: =SUM(L9:L9) -> 0 | N10: 44838
D12: Vào lúc …….giờ …….. phút, thứ ….. ngày …28…. tháng …01.. Năm 2022….
B13: Quản lý ST | D13: GSKV | F13: Trưởng nhóm kiểm kê | I13: Giám đốc ĐHBL | M13: Trưởng Phòng Kế Toán
B14: (Ký và ghi rõ họ tên) | D14: (Ký và ghi rõ họ tên) | F14: (Ký và ghi rõ họ tên) | I14: (Ký và ghi rõ họ tên) | M14: (Ký và ghi rõ họ tên)

Sheet Ecopark
I1: Mã hiệu: SBL.KDBL.QT.BM.01.02 Lần ban hành: 01 Ngày ban hành: 22/03/2018
A2: BẢNG CHÊNH LỆCH HÀNG HÓA KIỂM KÊ
A6: STT | B6: Loại Hàng | C6: Mã sản phẩm | D6: Mã Barcode | E6: Tên sản phẩm | F6: Giá bán lẻ | G6: Số lượng tồn phần mềm | H6: Số lượng tồn thực tế | I6: Chênh lệch | M6: Lý do ST giải trình | N6: Ngày điều chỉnh
I7: Chênh lệch thừa | K7: Chênh lệch thiếu
I8: Số lượng | J8: Trị giá thừa | K8: Số lượng | L8: Trị giá thiếu
A11: Tổng | I11: =SUM(I9:I10) -> 0 | J11: =SUM(J9:J10) -> 0 | K11: =SUM(K9:K10) -> 0 | L11: =SUM(L9:L10) -> 0 | N11: 45078
D13: Vào lúc …….giờ …….. phút, thứ ….. ngày …28…. tháng …01.. Năm 2022….
B14: Quản lý ST | D14: GSKV | F14: Trưởng nhóm kiểm kê | I14: Giám đốc ĐHBL | M14: Trưởng Phòng Kế Toán
B15: (Ký và ghi rõ họ tên) | D15: (Ký và ghi rõ họ tên) | F15: (Ký và ghi rõ họ tên) | I15: (Ký và ghi rõ họ tên) | M15: (Ký và ghi rõ họ tên)

Sheet Gamuda
I1: Mã hiệu: SBL.KDBL.QT.BM.01.02 Lần ban hành: 01 Ngày ban hành: 22/03/2018
A2: BẢNG CHÊNH LỆCH HÀNG HÓA KIỂM KÊ
A6: STT | B6: Loại Hàng | C6: Mã sản phẩm | D6: Mã Barcode | E6: Tên sản phẩm | F6: Giá bán lẻ | G6: Số lượng tồn phần mềm | H6: Số lượng tồn thực tế | I6: Chênh lệch | M6: Lý do ST giải trình | N6: Ngày điều chỉnh
I7: Chênh lệch thừa | K7: Chênh lệch thiếu
I8: Số lượng | J8: Trị giá thừa | K8: Số lượng | L8: Trị giá thiếu
B9: THỰC PHẨM | C9: 152848 | D9: 4990485007068 | E9: SEIKI- Bánh mochi socola trà xanh 30 chiếc | F9: 350000 | G9: -3 | H9: 0 | I9: =+H9-G9 -> 3 | J9: =+I9*F9 -> 1050000 | M9: tách set quà | N9: =TODAY() -> 46199
B10: THỰC PHẨM | C10: 153206 | D10: 4945202306102 | E10: SATOEN- Trà Sencha Special Hưng Long 20 túi (40g) | F10: 95000 | G10: -2 | H10: 0 | I10: =+H10-G10 -> 2 | J10: =+I10*F10 -> 190000 | M10: tách set quà | N10: =TODAY() -> 46199
B11: THỰC PHẨM | C11: 153250 | D11: 4902777204727 | E11: MEIJI- Socola bọc hạnh nhân 79g | F11: 95000 | G11: -2 | H11: 0 | I11: =+H11-G11 -> 2 | J11: =+I11*F11 -> 190000 | M11: tách set quà | N11: =TODAY() -> 46199
A12: Tổng | I12: =SUM(I9:I11) -> 7 | J12: =SUM(J9:J11) -> 1430000 | K12: =SUM(K9:K11) -> 0 | L12: =SUM(L9:L11) -> 0 | N12: =TODAY() -> 46199
D14: Vào lúc …….giờ …….. phút, thứ ….. ngày …28…. tháng …01.. Năm 2022….
B15: Quản lý ST | D15: GSKV | F15: Trưởng nhóm kiểm kê | I15: Giám đốc ĐHBL | M15: Trưởng Phòng Kế Toán
B16: (Ký và ghi rõ họ tên) | D16: (Ký và ghi rõ họ tên) | F16: (Ký và ghi rõ họ tên) | I16: (Ký và ghi rõ họ tên) | M16: (Ký và ghi rõ họ tên)

Sheet các mã không điều chỉnh
I1: Mã hiệu: SBL.KDBL.QT.BM.01.02 Lần ban hành: 01 Ngày ban hành: 22/03/2018
A2: BẢNG CHÊNH LỆCH HÀNG HÓA KIỂM KÊ
A6: STT | B6: Loại Hàng | C6: Mã sản phẩm | D6: Mã Barcode | E6: Tên sản phẩm | F6: Giá bán lẻ | G6: Số lượng tồn phần mềm | H6: Số lượng tồn thực tế | I6: Chênh lệch | M6: Lý do ST giải trình | N6: Ngày điều chỉnh
I7: Chênh lệch thừa | K7: Chênh lệch thiếu
I8: Số lượng | J8: Trị giá thừa | K8: Số lượng | L8: Trị giá thiếu
B9: THỰC PHẨM | C9: 153144 | D9: 4539114075230 | E9: VALOR SELECT- Dầu ăn hạt cải không cholesterol 1L | F9: 99000 | G9: 1 | H9: 0 | K9: -1 | L9: =+K9*F9 -> -99000 | M9: Bị mất | N9: 45276
A10: Tổng | I10: =SUM(I9:I9) -> 0 | J10: =SUM(J9:J9) -> 0 | K10: =SUM(K9:K9) -> -1 | L10: =SUM(L9:L9) -> -99000 | N10: 45276
D12: Vào lúc …….giờ …….. phút, thứ ….. ngày …28…. tháng …01.. Năm 2022….
B13: Quản lý ST | D13: GSKV | F13: Trưởng nhóm kiểm kê | I13: Giám đốc ĐHBL | M13: Trưởng Phòng Kế Toán
B14: (Ký và ghi rõ họ tên) | D14: (Ký và ghi rõ họ tên) | F14: (Ký và ghi rõ họ tên) | I14: (Ký và ghi rõ họ tên) | M14: (Ký và ghi rõ họ tên)

Sheet Hà Giang
I1: Mã hiệu: SBL.KDBL.QT.BM.01.02 Lần ban hành: 01 Ngày ban hành: 22/03/2018
A2: BẢNG CHÊNH LỆCH HÀNG HÓA KIỂM KÊ
A6: STT | B6: Loại Hàng | C6: Mã sản phẩm | D6: Mã Barcode | E6: Tên sản phẩm | F6: Giá bán lẻ | G6: Số lượng tồn phần mềm | H6: Số lượng tồn thực tế | I6: Chênh lệch | M6: Lý do ST giải trình | N6: Ngày điều chỉnh
I7: Chênh lệch thừa | K7: Chênh lệch thiếu
I8: Số lượng | J8: Trị giá thừa | K8: Số lượng | L8: Trị giá thiếu
B9: CHĂM SÓC SẮC ĐẸP | C9: 101712 | D9: 4513574036611 | E9: KUMANO YUSHI- Sữa dưỡng thể CN ý dĩ SPF 31(400ml) | F9: 320000 | G9: -1 | H9: 0 | I9: 1 | J9: 320000 | M9: tăng | N9: =TODAY() -> 46199
B10: CHĂM SÓC SẮC ĐẸP | C10: 101794 | D10: 4550516705464 | E10: SHISEIDO-Sữa rửa mặt Senka VitaC làm sáng da 100g | F10: 115000 | G10: -1 | H10: 0 | I10: 1 | J10: 115000 | M10: 101937 | N10: =TODAY() -> 46199
B11: CHĂM SÓC SẮC ĐẸP | C11: 101937 | D11: 1011042312005 | E11: SHISEIDO- Set SRM Senka Acnes + UNO hot clear gel | F11: 119000 | G11: 1 | H11: 0 | K11: -1 | L11: =+K11*F11 -> -119000 | N11: =TODAY() -> 46199
A12: Tổng | I12: =SUM(I9:I11) -> 2 | J12: =SUM(J9:J11) -> 435000 | K12: =SUM(K9:K11) -> -1 | L12: =SUM(L9:L11) -> -119000 | N12: =TODAY() -> 46199
D14: Vào lúc …….giờ …….. phút, thứ ….. ngày …28…. tháng …01.. Năm 2022….
B15: Quản lý ST | D15: GSKV | F15: Trưởng nhóm kiểm kê | I15: Giám đốc ĐHBL | M15: Trưởng Phòng Kế Toán
B16: (Ký và ghi rõ họ tên) | D16: (Ký và ghi rõ họ tên) | F16: (Ký và ghi rõ họ tên) | I16: (Ký và ghi rõ họ tên) | M16: (Ký và ghi rõ họ tên)

Sheet Lạng Sơn
I1: Mã hiệu: SBL.KDBL.QT.BM.01.02 Lần ban hành: 01 Ngày ban hành: 22/03/2018
A2: BẢNG CHÊNH LỆCH HÀNG HÓA KIỂM KÊ
A6: STT | B6: Loại Hàng | C6: Mã sản phẩm | D6: Mã Barcode | E6: Tên sản phẩm | F6: Giá bán lẻ | G6: Số lượng tồn phần mềm | H6: Số lượng tồn thực tế | I6: Chênh lệch | M6: Lý do ST giải trình | N6: Ngày điều chỉnh
I7: Chênh lệch thừa | K7: Chênh lệch thiếu
I8: Số lượng | J8: Trị giá thừa | K8: Số lượng | L8: Trị giá thiếu
A14: Tổng | I14: =SUM(I9:I13) -> 0 | J14: =SUM(J9:J13) -> 0 | K14: =SUM(K9:K13) -> 0 | L14: =SUM(L9:L13) -> 0 | N14: 44993
D16: Vào lúc …….giờ …….. phút, thứ ….. ngày …28…. tháng …01.. Năm 2022….
B17: Quản lý ST | D17: GSKV | F17: Trưởng nhóm kiểm kê | I17: Giám đốc ĐHBL | M17: Trưởng Phòng Kế Toán
B18: (Ký và ghi rõ họ tên) | D18: (Ký và ghi rõ họ tên) | F18: (Ký và ghi rõ họ tên) | I18: (Ký và ghi rõ họ tên) | M18: (Ký và ghi rõ họ tên)

Sheet Thanh Hóa
I1: Mã hiệu: SBL.KDBL.QT.BM.01.02 Lần ban hành: 01 Ngày ban hành: 22/03/2018
A2: BẢNG CHÊNH LỆCH HÀNG HÓA KIỂM KÊ
A6: STT | B6: Loại Hàng | C6: Mã sản phẩm | D6: Mã Barcode | E6: Tên sản phẩm | F6: Giá bán lẻ | G6: Số lượng tồn phần mềm | H6: Số lượng tồn thực tế | I6: Chênh lệch | M6: Lý do ST giải trình | N6: ghi chú
I7: Chênh lệch thừa | K7: Chênh lệch thiếu
I8: Số lượng | J8: Trị giá thừa | K8: Số lượng | L8: Trị giá thiếu
A21: Tổng | I21: =SUM(I9:I20) -> 0 | J21: =SUM(J9:J20) -> 0 | K21: =SUM(K9:K20) -> 0 | L21: =SUM(L9:L20) -> 0 | N21: 45309
D23: Vào lúc …….giờ …….. phút, thứ ….. ngày …28…. tháng …01.. Năm 2022….
B24: Quản lý ST | D24: GSKV | F24: Trưởng nhóm kiểm kê | I24: Giám đốc ĐHBL | M24: Trưởng Phòng Kế Toán
B25: (Ký và ghi rõ họ tên) | D25: (Ký và ghi rõ họ tên) | F25: (Ký và ghi rõ họ tên) | I25: (Ký và ghi rõ họ tên) | M25: (Ký và ghi rõ họ tên)

Sheet Sài Đồng
I1: Mã hiệu: SBL.KDBL.QT.BM.01.02 Lần ban hành: 01 Ngày ban hành: 22/03/2018
A2: BẢNG CHÊNH LỆCH HÀNG HÓA KIỂM KÊ
A6: STT | B6: Loại Hàng | C6: Mã sản phẩm | D6: Mã Barcode | E6: Tên sản phẩm | F6: Giá bán lẻ | G6: Số lượng tồn phần mềm | H6: Số lượng tồn thực tế | I6: Chênh lệch | M6: Lý do ST giải trình | N6: Ngày điều chỉnh
I7: Chênh lệch thừa | K7: Chênh lệch thiếu
I8: Số lượng | J8: Trị giá thừa | K8: Số lượng | L8: Trị giá thiếu
A33: Tổng | I33: =SUM(I9:I32) -> 0 | J33: =SUM(J9:J32) -> 0 | K33: =SUM(K9:K32) -> 0 | L33: =SUM(L9:L32) -> 0 | N33: 45264
D35: Vào lúc …….giờ …….. phút, thứ ….. ngày …28…. tháng …01.. Năm 2022….
B36: Quản lý ST | D36: GSKV | F36: Trưởng nhóm kiểm kê | I36: Giám đốc ĐHBL | M36: Trưởng Phòng Kế Toán
B37: (Ký và ghi rõ họ tên) | D37: (Ký và ghi rõ họ tên) | F37: (Ký và ghi rõ họ tên) | I37: (Ký và ghi rõ họ tên) | M37: (Ký và ghi rõ họ tên)

Sheet SĐ
I1: Mã hiệu: SBL.KDBL.QT.BM.01.02 Lần ban hành: 01 Ngày ban hành: 22/03/2018
A2: BẢNG CHÊNH LỆCH HÀNG HÓA KIỂM KÊ
A6: STT | B6: Loại Hàng | C6: Mã sản phẩm | D6: Mã Barcode | E6: Tên sản phẩm | F6: Giá bán lẻ | G6: Số lượng tồn phần mềm | H6: Số lượng tồn thực tế | I6: Chênh lệch | M6: Lý do ST giải trình | N6: Ngày điều chỉnh
I7: Chênh lệch thừa | K7: Chênh lệch thiếu
I8: Số lượng | J8: Trị giá thừa | K8: Số lượng | L8: Trị giá thiếu
A23: Tổng | I23: =SUM(I9:I22) -> 0 | J23: =SUM(J9:J22) -> 0 | K23: =SUM(K9:K22) -> 0 | L23: =SUM(L9:L22) -> 0 | N23: 45314
D25: Vào lúc …….giờ …….. phút, thứ ….. ngày …28…. tháng …01.. Năm 2022….
B26: Quản lý ST | D26: GSKV | F26: Trưởng nhóm kiểm kê | I26: Giám đốc ĐHBL | M26: Trưởng Phòng Kế Toán
B27: (Ký và ghi rõ họ tên) | D27: (Ký và ghi rõ họ tên) | F27: (Ký và ghi rõ họ tên) | I27: (Ký và ghi rõ họ tên) | M27: (Ký và ghi rõ họ tên)

Sheet Vĩnh Phúc
I1: Mã hiệu: SBL.KDBL.QT.BM.01.02 Lần ban hành: 01 Ngày ban hành: 22/03/2018
A2: BẢNG CHÊNH LỆCH HÀNG HÓA KIỂM KÊ
A6: STT | B6: Loại Hàng | C6: Mã sản phẩm | D6: Mã Barcode | E6: Tên sản phẩm | F6: Giá bán lẻ | G6: Số lượng tồn phần mềm | H6: Số lượng tồn thực tế | I6: Chênh lệch | M6: Lý do ST giải trình | N6: Ngày điều chỉnh
I7: Chênh lệch thừa | K7: Chênh lệch thiếu
I8: Số lượng | J8: Trị giá thừa | K8: Số lượng | L8: Trị giá thiếu
A18: Tổng | I18: =SUM(I9:I17) -> 0 | J18: =SUM(J9:J17) -> 0 | K18: =SUM(K9:K17) -> 0 | L18: =SUM(L9:L17) -> 0 | N18: 44739
D20: Vào lúc …….giờ …….. phút, thứ ….. ngày …28…. tháng …01.. Năm 2022….
B21: Quản lý ST | D21: GSKV | F21: Trưởng nhóm kiểm kê | I21: Giám đốc ĐHBL | M21: Trưởng Phòng Kế Toán
B22: (Ký và ghi rõ họ tên) | D22: (Ký và ghi rõ họ tên) | F22: (Ký và ghi rõ họ tên) | I22: (Ký và ghi rõ họ tên) | M22: (Ký và ghi rõ họ tên)

Sheet Tuyên Quang
I1: Mã hiệu: SBL.KDBL.QT.BM.01.02 Lần ban hành: 01 Ngày ban hành: 22/03/2018
A2: BẢNG CHÊNH LỆCH HÀNG HÓA KIỂM KÊ
A6: STT | B6: Loại Hàng | C6: Mã sản phẩm | D6: Mã Barcode | E6: Tên sản phẩm | F6: Giá bán lẻ | G6: Số lượng tồn phần mềm | H6: Số lượng tồn thực tế | I6: Chênh lệch | M6: Lý do ST giải trình | N6: Ngày điều chỉnh
I7: Chênh lệch thừa | K7: Chênh lệch thiếu
I8: Số lượng | J8: Trị giá thừa | K8: Số lượng | L8: Trị giá thiếu
B9: ĐỒ CHO MẸ BÉ | C9: 121520 | D9: 1217032304283 | E9: ANYZOO- Yếm quàng cổ cúc bấm cho bé | F9: 25000 | G9: -2 | H9: 0 | I9: 2 | J9: =+I9*F9 -> 50000 | M9: tăng | N9: 45239
A10: Tổng | I10: =SUM(I9:I9) -> 2 | J10: =SUM(J9:J9) -> 50000 | K10: =SUM(K9:K9) -> 0 | L10: =SUM(L9:L9) -> 0 | N10: 45239
D12: Vào lúc …….giờ …….. phút, thứ ….. ngày …28…. tháng …01.. Năm 2022….
B13: Quản lý ST | D13: GSKV | F13: Trưởng nhóm kiểm kê | I13: Giám đốc ĐHBL | M13: Trưởng Phòng Kế Toán
B14: (Ký và ghi rõ họ tên) | D14: (Ký và ghi rõ họ tên) | F14: (Ký và ghi rõ họ tên) | I14: (Ký và ghi rõ họ tên) | M14: (Ký và ghi rõ họ tên)

Sheet Đồng Hới
I1: Mã hiệu: SBL.KDBL.QT.BM.01.02 Lần ban hành: 01 Ngày ban hành: 22/03/2018
A2: BẢNG CHÊNH LỆCH HÀNG HÓA KIỂM KÊ
A6: STT | B6: Loại Hàng | C6: Mã sản phẩm | D6: Mã Barcode | E6: Tên sản phẩm | F6: Giá bán lẻ | G6: Số lượng tồn phần mềm | H6: Số lượng tồn thực tế | I6: Chênh lệch | M6: Lý do ST giải trình | N6: Ngày điều chỉnh
I7: Chênh lệch thừa | K7: Chênh lệch thiếu
I8: Số lượng | J8: Trị giá thừa | K8: Số lượng | L8: Trị giá thiếu
B9: NHÀ CỬA ĐỜI SỐNG | C9: 134011 | D9: 4987176140296 | E9: P&G- Viên giặt xả Gel Bold 3D hương hoa xanh 36v | F9: 205000 | G9: -1 | H9: 0 | I9: 1 | J9: 205000 | M9: 134010 | N9: 45239
B10: NHÀ CỬA ĐỜI SỐNG | C10: 134010 | D10: 4987176140203 | E10: P&G- Viên giặt xả Gel Bold 4D hương hoa hồng 36v | F10: 205000 | G10: 1 | H10: 0 | K10: -1 | L10: =+K10*F10 -> -205000 | N10: 45239
A11: Tổng | I11: =SUM(I9:I10) -> 1 | J11: =SUM(J9:J10) -> 205000 | K11: =SUM(K9:K10) -> -1 | L11: =SUM(L9:L10) -> -205000 | N11: 45239
D13: Vào lúc …….giờ …….. phút, thứ ….. ngày …28…. tháng …01.. Năm 2022….
B14: Quản lý ST | D14: GSKV | F14: Trưởng nhóm kiểm kê | I14: Giám đốc ĐHBL | M14: Trưởng Phòng Kế Toán
B15: (Ký và ghi rõ họ tên) | D15: (Ký và ghi rõ họ tên) | F15: (Ký và ghi rõ họ tên) | I15: (Ký và ghi rõ họ tên) | M15: (Ký và ghi rõ họ tên)

Sheet Bắc Ninh
I1: Mã hiệu: SBL.KDBL.QT.BM.01.02 Lần ban hành: 01 Ngày ban hành: 22/03/2018
A2: BẢNG CHÊNH LỆCH HÀNG HÓA KIỂM KÊ
A6: STT | B6: Loại Hàng | C6: Mã sản phẩm | D6: Mã Barcode | E6: Tên sản phẩm | F6: Giá bán lẻ | G6: Số lượng tồn phần mềm | H6: Số lượng tồn thực tế | I6: Chênh lệch | M6: Lý do ST giải trình | N6: Ngày điều chỉnh
I7: Chênh lệch thừa | K7: Chênh lệch thiếu
I8: Số lượng | J8: Trị giá thừa | K8: Số lượng | L8: Trị giá thiếu
A19: Tổng | I19: =SUM(I9:I18) -> 0 | J19: =SUM(J9:J18) -> 0 | K19: =SUM(K9:K18) -> 0 | L19: =SUM(L9:L18) -> 0 | N19: 45117
D21: Vào lúc …….giờ …….. phút, thứ ….. ngày …28…. tháng …01.. Năm 2022….
B22: Quản lý ST | D22: GSKV | F22: Trưởng nhóm kiểm kê | I22: Giám đốc ĐHBL | M22: Trưởng Phòng Kế Toán
B23: (Ký và ghi rõ họ tên) | D23: (Ký và ghi rõ họ tên) | F23: (Ký và ghi rõ họ tên) | I23: (Ký và ghi rõ họ tên) | M23: (Ký và ghi rõ họ tên)

Sheet Hải Phòng
I1: Mã hiệu: SBL.KDBL.QT.BM.01.02 Lần ban hành: 01 Ngày ban hành: 22/03/2018
A2: BẢNG CHÊNH LỆCH HÀNG HÓA KIỂM KÊ
A6: STT | B6: Loại Hàng | C6: Mã sản phẩm | D6: Mã Barcode | E6: Tên sản phẩm | F6: Giá bán lẻ | G6: Số lượng tồn phần mềm | H6: Số lượng tồn thực tế | I6: Chênh lệch | M6: Lý do ST giải trình | N6: Ngày điều chỉnh
I7: Chênh lệch thừa | K7: Chênh lệch thiếu
I8: Số lượng | J8: Trị giá thừa | K8: Số lượng | L8: Trị giá thiếu
A10: Tổng | I10: =SUM(I9:I9) -> 0 | J10: =SUM(J9:J9) -> 0 | K10: =SUM(K9:K9) -> 0 | L10: =SUM(L9:L9) -> 0 | N10: 44812
D12: Vào lúc …….giờ …….. phút, thứ ….. ngày …28…. tháng …01.. Năm 2022….
B13: Quản lý ST | D13: GSKV | F13: Trưởng nhóm kiểm kê | I13: Giám đốc ĐHBL | M13: Trưởng Phòng Kế Toán
B14: (Ký và ghi rõ họ tên) | D14: (Ký và ghi rõ họ tên) | F14: (Ký và ghi rõ họ tên) | I14: (Ký và ghi rõ họ tên) | M14: (Ký và ghi rõ họ tên)

Sheet Đông Anh
I1: Mã hiệu: SBL.KDBL.QT.BM.01.02 Lần ban hành: 01 Ngày ban hành: 22/03/2018
A2: BẢNG CHÊNH LỆCH HÀNG HÓA KIỂM KÊ
A6: STT | B6: Loại Hàng | C6: Mã sản phẩm | D6: Mã Barcode | E6: Tên sản phẩm | F6: Giá bán lẻ | G6: Số lượng tồn phần mềm | H6: Số lượng tồn thực tế | I6: Chênh lệch | M6: Lý do ST giải trình | N6: Ngày điều chỉnh
I7: Chênh lệch thừa | K7: Chênh lệch thiếu
I8: Số lượng | J8: Trị giá thừa | K8: Số lượng | L8: Trị giá thiếu
A10: Tổng | I10: =SUM(I9:I9) -> 0 | J10: =SUM(J9:J9) -> 0 | K10: =SUM(K9:K9) -> 0 | L10: =SUM(L9:L9) -> 0 | N10: 45023
D12: Vào lúc …….giờ …….. phút, thứ ….. ngày …28…. tháng …01.. Năm 2022….
B13: Quản lý ST | D13: GSKV | F13: Trưởng nhóm kiểm kê | I13: Giám đốc ĐHBL | M13: Trưởng Phòng Kế Toán
B14: (Ký và ghi rõ họ tên) | D14: (Ký và ghi rõ họ tên) | F14: (Ký và ghi rõ họ tên) | I14: (Ký và ghi rõ họ tên) | M14: (Ký và ghi rõ họ tên)

Sheet NVL
I1: Mã hiệu: SBL.KDBL.QT.BM.01.02 Lần ban hành: 01 Ngày ban hành: 22/03/2018
A2: BẢNG CHÊNH LỆCH HÀNG HÓA KIỂM KÊ
A6: STT | B6: Loại Hàng | C6: Mã sản phẩm | D6: Mã Barcode | E6: Tên sản phẩm | F6: Giá bán lẻ | G6: Số lượng tồn phần mềm | H6: Số lượng tồn thực tế | I6: Chênh lệch | M6: Lý do ST giải trình | N6: Ngày điều chỉnh
I7: Chênh lệch thừa | K7: Chênh lệch thiếu
I8: Số lượng | J8: Trị giá thừa | K8: Số lượng | L8: Trị giá thiếu
A21: Tổng | I21: =SUM(I9:I20) -> 0 | J21: =SUM(J9:J20) -> 0 | K21: =SUM(K9:K20) -> 0 | L21: =SUM(L9:L20) -> 0 | N21: 44756
D23: Vào lúc …….giờ …….. phút, thứ ….. ngày …28…. tháng …01.. Năm 2022….
B24: Quản lý ST | D24: GSKV | F24: Trưởng nhóm kiểm kê | I24: Giám đốc ĐHBL | M24: Trưởng Phòng Kế Toán
B25: (Ký và ghi rõ họ tên) | D25: (Ký và ghi rõ họ tên) | F25: (Ký và ghi rõ họ tên) | I25: (Ký và ghi rõ họ tên) | M25: (Ký và ghi rõ họ tên)

Sheet Ba Đồn
I1: Mã hiệu: SBL.KDBL.QT.BM.01.02 Lần ban hành: 01 Ngày ban hành: 22/03/2018
A2: BẢNG CHÊNH LỆCH HÀNG HÓA KIỂM KÊ
A6: STT | B6: Loại Hàng | C6: Mã sản phẩm | D6: Mã Barcode | E6: Tên sản phẩm | F6: Giá bán lẻ | G6: Số lượng tồn phần mềm | H6: Số lượng tồn thực tế | I6: Chênh lệch | M6: Lý do ST giải trình | N6: Ngày điều chỉnh
I7: Chênh lệch thừa | K7: Chênh lệch thiếu
I8: Số lượng | J8: Trị giá thừa | K8: Số lượng | L8: Trị giá thiếu
B9: CHĂM SÓC SỨC KHỎE | C9: 110447 | D9: 4971493001880 | E9: ORIHIRO- Trà giảm mỡ bụng Genpi (3g x 60 gói) | F9: 180000 | G9: 4 | H9: 0 | K9: =+H9-G9 -> -4 | L9: =+K9*F9 -> -720000 | M9: ko rõ nguyên nhân | N9: 45240
B10: CHĂM SÓC SỨC KHỎE | C10: 110081 | D10: 4937224925658 | E10: JAPAN ALGAE- Tảo xoắn SPIRULINA 2200 viên | F10: 495000 | G10: 5 | H10: 3 | K10: =+H10-G10 -> -2 | L10: =+K10*F10 -> -990000 | M10: ko rõ nguyên nhân | N10: 45240
B11: CHĂM SÓC SỨC KHỎE | C11: 110304 | D11: 4511413404133 | E11: DHC- Viên bổ sung vitaminC 120 viên | F11: 140000 | G11: 12 | H11: 10 | K11: =+H11-G11 -> -2 | L11: =+K11*F11 -> -280000 | M11: ko rõ nguyên nhân | N11: 45240
B12: CHĂM SÓC SỨC KHỎE | C12: 110402 | D12: 4987415993508 | E12: SHISEIDO- The Collagen EXR (50ml x 10 lọ) | F12: 899000 | G12: 13 | H12: 11 | K12: =+H12-G12 -> -2 | L12: =+K12*F12 -> -1798000 | M12: ko rõ nguyên nhân | N12: 45240
B13: CHĂM SÓC SỨC KHỎE | C13: 110537 | D13: 4589622170972 | E13: Viên Uống Chống Nắng UV Plus+ Block100 (45v) | F13: 375000 | G13: 3 | H13: 1 | K13: =+H13-G13 -> -2 | L13: =+K13*F13 -> -750000 | M13: ko rõ nguyên nhân | N13: 45240
B14: CHĂM SÓC SỨC KHỎE | C14: 110688 | D14: 4573533690384 | E14: PILLBOX- Viên giải rượu Kanpai Ukon Gold 5v New | F14: 145000 | G14: 7 | H14: 5 | K14: =+H14-G14 -> -2 | L14: =+K14*F14 -> -290000 | M14: ko rõ nguyên nhân | N14: 45240
B15: CHĂM SÓC SỨC KHỎE | C15: 176444 | D15: 4902087156587 | E15: TAMANOI- Dấm giảm cân dấm táo&mật ong vị mơ 500ml | F15: 129000 | G15: 2 | H15: 0 | K15: =+H15-G15 -> -2 | L15: =+K15*F15 -> -258000 | M15: ko rõ nguyên nhân | N15: 45240
B16: CHĂM SÓC SỨC KHỎE | C16: 110079 | D16: 4937224924613 | E16: JAPAN ALGAE- Tảo xoắn Spirulina bổ sung SGF 1500v | F16: 450000 | G16: 2 | H16: 1 | K16: =+H16-G16 -> -1 | L16: =+K16*F16 -> -450000 | M16: ko rõ nguyên nhân | N16: 45240
B17: CHĂM SÓC SỨC KHỎE | C17: 110080 | D17: 4937224925634 | E17: JAPAN ALGAE- Tảo xoắn SPIRULINA Nhật Bản1500Vviên | F17: 420000 | G17: 1 | H17: 0 | K17: =+H17-G17 -> -1 | L17: =+K17*F17 -> -420000 | M17: ko rõ nguyên nhân | N17: 45240
B18: CHĂM SÓC SỨC KHỎE | C18: 110246 | D18: 4589788400012 | E18: GH CREATION- Viên uống tăng chiều cao 270 viên | F18: 890000 | G18: 2 | H18: 1 | K18: =+H18-G18 -> -1 | L18: =+K18*F18 -> -890000 | M18: ko rõ nguyên nhân | N18: 45240
B19: CHĂM SÓC SỨC KHỎE | C19: 110311 | D19: 4562193140575 | E19: NOGUCHI- Viên b.sung DHA&EPA chứa bạch quả 60v | F19: 550000 | G19: 2 | H19: 1 | K19: =+H19-G19 -> -1 | L19: =+K19*F19 -> -550000 | M19: ko rõ nguyên nhân | N19: 45240
B20: CHĂM SÓC SỨC KHỎE | C20: 110403 | D20: 4987415993454 | E20: SHISEIDO- The Collagen NEW (50ml x 10 lọ) | F20: 595000 | G20: 3 | H20: 2 | K20: =+H20-G20 -> -1 | L20: =+K20*F20 -> -595000 | M20: ko rõ nguyên nhân | N20: 45240
... B25: CHĂM SÓC SỨC KHỎE | C25: 174051 | D25: 4987107619792 | E25: TRANSINO- Viên uống trị nám White C Clear 120v | F25: 550000 | G25: 9 | H25: 8 | K25: =+H25-G25 -> -1 | L25: =+K25*F25 -> -550000 | M25: ko rõ nguyên nhân | N25: 45240
B26: CHĂM SÓC SỨC KHỎE | C26: 230095 | D26: 2301012209008 | E26: IKIMOTO-Viên chống lão hóa trẻ tế bàoNMN15000+ 90v | F26: 4250000 | G26: 1 | H26: 0 | K26: =+H26-G26 -> -1 | L26: =+K26*F26 -> -4250000 | N26: 45240
B27: CHĂM SÓC SỨC KHỎE | C27: 110472 | D27: 4511606904853 | E27: CRESCENDO- Tảo tăng ch.cao Shinshin Kakumei 300v | F27: 450000 | G27: 0 | H27: 1 | I27: =+H27-G27 -> 1 | J27: =+I27*F27 -> 450000 | K27: =+H27-G27 -> 1 | L27: =+K27*F27 -> 450000 | M27: ko rõ nguyên nhân | N27: 45240
A28: Tổng | I28: =SUM(I9:I27) -> 1 | J28: =SUM(J9:J27) -> 450000 | K28: =SUM(K9:K27) -> -26 | L28: =SUM(L9:L27) -> -13736000 | N28: 45240
D30: Vào lúc …….giờ …….. phút, thứ ….. ngày …28…. tháng …01.. Năm 2022….
B31: Quản lý ST | D31: GSKV | F31: Trưởng nhóm kiểm kê | I31: Giám đốc ĐHBL | M31: Trưởng Phòng Kế Toán
B32: (Ký và ghi rõ họ tên) | D32: (Ký và ghi rõ họ tên) | F32: (Ký và ghi rõ họ tên) | I32: (Ký và ghi rõ họ tên) | M32: (Ký và ghi rõ họ tên)

Sheet Hạ Long (2)
I1: Mã hiệu: SBL.KDBL.QT.BM.01.02 Lần ban hành: 01 Ngày ban hành: 22/03/2018
A2: BẢNG CHÊNH LỆCH HÀNG HÓA KIỂM KÊ
A6: STT | B6: Loại Hàng | C6: Mã sản phẩm | D6: Mã Barcode | E6: Tên sản phẩm | F6: Giá bán lẻ | G6: Số lượng tồn phần mềm | H6: Số lượng tồn thực tế | I6: Chênh lệch | M6: Lý do ST giải trình | N6: Ngày điều chỉnh
I7: Chênh lệch thừa | K7: Chênh lệch thiếu
I8: Số lượng | J8: Trị giá thừa | K8: Số lượng | L8: Trị giá thiếu
B9: THỰC PHẨM | C9: 152785 | D9: 4903015500038 | E9: YBC- Snack khoai tây Chipstar vị rong biển (50g) | F9: 40000 | G9: -1 | H9: 0 | I9: 1 | J9: 40000 | M9: tăng | N9: 45142
A10: Tổng | I10: =SUM(I9:I9) -> 1 | J10: =SUM(J9:J9) -> 40000 | K10: =SUM(K9:K9) -> 0 | L10: =SUM(L9:L9) -> 0 | N10: 45142
D12: Vào lúc …….giờ …….. phút, thứ ….. ngày …28…. tháng …01.. Năm 2022….
B13: Quản lý ST | D13: GSKV | F13: Trưởng nhóm kiểm kê | I13: Giám đốc ĐHBL | M13: Trưởng Phòng Kế Toán
B14: (Ký và ghi rõ họ tên) | D14: (Ký và ghi rõ họ tên) | F14: (Ký và ghi rõ họ tên) | I14: (Ký và ghi rõ họ tên) | M14: (Ký và ghi rõ họ tên)

Sheet Thái Bình
I1: Mã hiệu: SBL.KDBL.QT.BM.01.02 Lần ban hành: 01 Ngày ban hành: 22/03/2018
A2: BẢNG CHÊNH LỆCH HÀNG HÓA KIỂM KÊ
A6: STT | B6: Loại Hàng | C6: Mã sản phẩm | D6: Mã Barcode | E6: Tên sản phẩm | F6: Giá bán lẻ | G6: Số lượng tồn phần mềm | H6: Số lượng tồn thực tế | I6: Chênh lệch | M6: Lý do ST giải trình | N6: Ngày điều chỉnh
I7: Chênh lệch thừa | K7: Chênh lệch thiếu
I8: Số lượng | J8: Trị giá thừa | K8: Số lượng | L8: Trị giá thiếu
B9: CHĂM SÓC SẮC ĐẸP | C9: 100015 | D9: 4971710306378 | E9: KOSE- Miếng lột mụn đầu đen Softymo 10 miếng | F9: 120000 | G9: -1 | H9: 0 | I9: 1 | J9: 120000 | M9: không rõ nguyên nhân | N9: 45239
B10: NHÀ CỬA ĐỜI SỐNG | C10: 130489 | D10: 4956810234806 | E10: KOKUBO- Sảp khử mùi toilet hoa oải hương 200ml | F10: 45000 | G10: -1 | H10: 0 | I10: 1 | J10: 45000 | M10: bán nhầm sang mã 130493 | N10: 45239
B11: NHÀ CỬA ĐỜI SỐNG | C11: 134045 | D11: 4546490505527 | E11: LIVING- BÌNH GIỮ NHIỆT NẮP VẶN ENJOY TRẮNG 480ML | F11: 190000 | G11: -1 | H11: 0 | I11: 1 | J11: 190000 | M11: bán nhầm sang mã 134047 | N11: 45239
B12: THỰC PHẨM | C12: 174600 | D12: 4901551368051 | E12: KRACIE- Kẹo ngậm khử mùi bạc hà the mát Frisk 35g | F12: 95000 | G12: -1 | H12: 0 | I12: 1 | J12: 95000 | M12: bán nhầm sang mã 174599 | N12: 45239
B13: NHÀ CỬA ĐỜI SỐNG | C13: 130493 | D13: 4956810234844 | E13: KOKUBO- Sáp khử mùi không khí hoa oải hương 200ml | F13: 45000 | G13: 1 | H13: 0 | K13: -1 | L13: =+K13*F13 -> -45000 | N13: 45239
B14: NHÀ CỬA ĐỜI SỐNG | C14: 134047 | D14: 4546490505541 | E14: LIVING- BÌNH GIỮ NHIỆT NẮP VẶN ENJOY ĐEN 480ML | F14: 190000 | G14: 1 | H14: 0 | K14: -1 | L14: =+K14*F14 -> -190000 | N14: 45239
B15: THỰC PHẨM | C15: 174599 | D15: 4901551368044 | E15: KRACIE- Kẹo ngậm khử mùi bạc hà dịu nhẹ Frisk 35g | F15: 95000 | G15: 1 | H15: 0 | K15: -1 | L15: =+K15*F15 -> -95000 | N15: 45239
A16: Tổng | I16: =SUM(I9:I15) -> 4 | J16: =SUM(J9:J15) -> 450000 | K16: =SUM(K9:K15) -> -3 | L16: =SUM(L9:L15) -> -330000 | N16: 45239
D18: Vào lúc …….giờ …….. phút, thứ ….. ngày …28…. tháng …01.. Năm 2022….
B19: Quản lý ST | D19: GSKV | F19: Trưởng nhóm kiểm kê | I19: Giám đốc ĐHBL | M19: Trưởng Phòng Kế Toán
B20: (Ký và ghi rõ họ tên) | D20: (Ký và ghi rõ họ tên) | F20: (Ký và ghi rõ họ tên) | I20: (Ký và ghi rõ họ tên) | M20: (Ký và ghi rõ họ tên)

Sheet Phú Thọ - Việt Trì
I1: Mã hiệu: SBL.KDBL.QT.BM.01.02 Lần ban hành: 01 Ngày ban hành: 22/03/2018
A2: BẢNG CHÊNH LỆCH HÀNG HÓA KIỂM KÊ
A6: STT | B6: Loại Hàng | C6: Mã sản phẩm | D6: Mã Barcode | E6: Tên sản phẩm | F6: Giá bán lẻ | G6: Số lượng tồn phần mềm | H6: Số lượng tồn thực tế | I6: Chênh lệch | M6: Lý do ST giải trình | N6: Ngày điều chỉnh
I7: Chênh lệch thừa | K7: Chênh lệch thiếu
I8: Số lượng | J8: Trị giá thừa | K8: Số lượng | L8: Trị giá thiếu
A12: Tổng | I12: =SUM(I9:I11) -> 0 | J12: =SUM(J9:J11) -> 0 | K12: =SUM(K9:K11) -> 0 | L12: =SUM(L9:L11) -> 0 | N12: 45016
D14: Vào lúc …….giờ …….. phút, thứ ….. ngày …28…. tháng …01.. Năm 2022….
B15: Quản lý ST | D15: GSKV | F15: Trưởng nhóm kiểm kê | I15: Giám đốc ĐHBL | M15: Trưởng Phòng Kế Toán
B16: (Ký và ghi rõ họ tên) | D16: (Ký và ghi rõ họ tên) | F16: (Ký và ghi rõ họ tên) | I16: (Ký và ghi rõ họ tên) | M16: (Ký và ghi rõ họ tên)

Sheet Đông Anh 
I1: Mã hiệu: SBL.KDBL.QT.BM.01.02 Lần ban hành: 01 Ngày ban hành: 22/03/2018
A2: BẢNG CHÊNH LỆCH HÀNG HÓA KIỂM KÊ
A6: STT | B6: Loại Hàng | C6: Mã sản phẩm | D6: Mã Barcode | E6: Tên sản phẩm | F6: Giá bán lẻ | G6: Số lượng tồn phần mềm | H6: Số lượng tồn thực tế | I6: Chênh lệch | M6: Lý do ST giải trình | N6: Ngày điều chỉnh
I7: Chênh lệch thừa | K7: Chênh lệch thiếu
I8: Số lượng | J8: Trị giá thừa | K8: Số lượng | L8: Trị giá thiếu
A15: Tổng | I15: =SUM(I9:I14) -> 0 | J15: =SUM(J9:J14) -> 0 | K15: =SUM(K9:K14) -> 0 | L15: =SUM(L9:L14) -> 0 | N15: 45072
D17: Vào lúc …….giờ …….. phút, thứ ….. ngày …28…. tháng …01.. Năm 2022….
B18: Quản lý ST | D18: GSKV | F18: Trưởng nhóm kiểm kê | I18: Giám đốc ĐHBL | M18: Trưởng Phòng Kế Toán
B19: (Ký và ghi rõ họ tên) | D19: (Ký và ghi rõ họ tên) | F19: (Ký và ghi rõ họ tên) | I19: (Ký và ghi rõ họ tên) | M19: (Ký và ghi rõ họ tên)

Sheet Đề xuất
A1: Công ty Cổ phần Sakuko Việt Nam
A2: Phòng Kinh doanh Bán lẻ
A3: CT1 ParkView, số 3 Vũ Phạm Hàm, Trung Hoà, Cầu Giấy, Hà Nội
A4: ĐƠN ĐỀ XUẤT HỖ TRỢ/ TỔNG HỢP GIÁ TRỊ ĐỀN BÙ CHÊNH LỆCH KIỂM KÊ
B6: Kính gửi: Ban Giám đốc Công ty TNHH Sakuko Việt Nam
B7: Đại diện siêu thị Trần Đăng Ninh là Nguyễn Thị Duyên
B8: Trong đợt kiểm kê tổng tại siêu thị Trần Đăng Ninh ngày 13.05.2026 bộ phận kiểm kê đã chốt ra số liệu kiểm kê cuối cùng cho Trần Đăng Ninh như sau:
A9: BẢNG TỔNG HỢP LÝ DO GIẢI TRÌNH BBKK TRẦN ĐĂNG NINH
A10: STT | B10: Lý do | C10: Số lượng Chênh lệch (+) | D10: Số lượng Chênh lệch (-) | E10: GIÁ TRỊ (+) | F10: GIÁ TRỊ (-) | G10: CL | H10: Đền bù | I10: Ghi chú BPKK | J10: Check
A11: 1 | B11: Không rõ nguyên nhân | C11: 4324 | D11: 3533 | E11: 205297680 | F11: 173914595 | G11: =E11-F11 -> 31383085
A12: 2 | B12: Nhầm mã với nhau | C12: =+C13-C11 -> 3036 | D12: =+D13-D11 -> 3042.459 | E12: =+E13-E11 -> 5.8599991e+08 | F12: =+F13-F11 -> 558395250 | G12: =+G13-G11 -> 27604662
C13: 7360 | D13: 6575.459 | E13: 7.9129759e+08 | F13: 732309845 | G13: =+E13-F13 -> 58987748
B14: Doanh thu tính từ 04/06/2025 đến 13/05/2026 | D14: 32174826746 | F14: Tỉ lệ giới hạn | G14: 0.0009
B15: Số QL siêu thị | C15: 1 | F15: Tỉ lệ thực tế | G15: 0
B16: Số Phó Quản lý | F16: Thực tế thất thoát | G16: =+H13 -> 0 | H16: 1479190.2
B17: Số NVBH | C17: 25 | F17: Đền bù
A19: Đại diện siêu thị Trần Đăng Ninh chúng em viết đề xuất tổng số tiền đền bù do không quản lý được hàng hóa dẫn đến thất thoát, chúng em xin sẽ được thanh toán và phân bổ như sau:
A20: STT | B20: Họ và tên | C20: Chức vụ | D20: Mã nhân viên | E20: Ngày bắt đầu làm việc | F20: Ngày kết thúc hoặc điều chuyển | G20: Số ngày làm việc tại siêu thị | H20: Hệ số | I20: Số ngày LV*hệ số | J20: Tổng Tiền Thưởng/Phạt | K20: Ghi chú | L20: Chữ ký nhân viên
A21: 1 | B21: Lương Thị Thanh Thương | C21: QL | D21: ST731 | E21: 45812 | F21: 46155 | G21: =DATEDIF(E21,F21,"d") -> 343 | H21: 3 | I21: =+H21*G21 -> 1029 | J21: =($G$17/$I$50)*I21 -> 0
A22: 2 | B22: Nguyễn Đình Duy | C22: NVBH | D22: 20328 | E22: 45812 | F22: 46081 | G22: =DATEDIF(E22,F22,"d") -> 269 | H22: 1 | I22: =+H22*G22 -> 269 | J22: =($G$17/$I$50)*I22 -> 0
A23: 3 | B23: Nguyễn Đình Duy | C23: chuyên viên | D23: 20328 | E23: 46082 | F23: 46156 | G23: =DATEDIF(E23,F23,"d") -> 74 | H23: 1.5 | I23: =+H23*G23 -> 111 | J23: =($G$17/$I$50)*I23 -> 0
A24: 4 | B24: Lê Hiền Trang | C24: NVBH | D24: 20330 | E24: 45812 | F24: 46052 | G24: =DATEDIF(E24,F24,"d") -> 240 | H24: 1 | I24: =+H24*G24 -> 240 | J24: =($G$17/$I$50)*I24 -> 0
A25: 5 | B25: Lê Hiền Trang | C25: chuyên viên | D25: 20330 | E25: 46054 | F25: 46157 | G25: =DATEDIF(E25,F25,"d") -> 103 | H25: 1.5 | I25: =+H25*G25 -> 154.5 | J25: =($G$17/$I$50)*I25 -> 0
A26: 6 | B26: Nguyễn Thị Thu | C26: NVBH | D26: 21244 | E26: 46090 | F26: 46158 | G26: =DATEDIF(E26,F26,"d") -> 68 | H26: 1 | I26: =+H26*G26 -> 68 | J26: =($G$17/$I$50)*I26 -> 0
A27: 7 | B27: Nghiêm Huệ Linh | C27: NVBH | D27: 21246 | E27: 46094 | F27: 46159 | G27: =DATEDIF(E27,F27,"d") -> 65 | H27: 1 | I27: =+H27*G27 -> 65 | J27: =($G$17/$I$50)*I27 -> 0
A28: 8 | B28: Đào Thị Hà | C28: NVBH | D28: 21257 | E28: 46115 | F28: 46160 | G28: =DATEDIF(E28,F28,"d") -> 45 | H28: 1 | I28: =+H28*G28 -> 45 | J28: =($G$17/$I$50)*I28 -> 0
A29: 9 | B29: Nguyễn Hoàng Anh | C29: NVBH | D29: 21260 | E29: 46116 | F29: 46161 | G29: =DATEDIF(E29,F29,"d") -> 45 | H29: 1 | I29: =+H29*G29 -> 45 | J29: =($G$17/$I$50)*I29 -> 0
A30: 10 | B30: Vũ Thị Hoa | C30: NVBH | D30: 21262 | E30: 46118 | F30: 46162 | G30: =DATEDIF(E30,F30,"d") -> 44 | H30: 1 | I30: =+H30*G30 -> 44 | J30: =($G$17/$I$50)*I30 -> 0
A31: 11 | B31: Phạm Thị Diễm | C31: NVBH | D31: 21265 | E31: 46120 | F31: 46163 | G31: =DATEDIF(E31,F31,"d") -> 43 | H31: 1 | I31: =+H31*G31 -> 43 | J31: =($G$17/$I$50)*I31 -> 0
A32: 12 | B32: Quách Thị Mai Quỳnh | C32: NVBH | D32: 20524 | E32: 46125 | F32: 46142 | G32: =DATEDIF(E32,F32,"d") -> 17 | H32: 1 | I32: =+H32*G32 -> 17 | J32: =($G$17/$I$50)*I32 -> 0
A33: 13 | B33: Quách Thị Mai Quỳnh | C33: chuyên viên | D33: 20524 | E33: 46143 | F33: 46155 | G33: =DATEDIF(E33,F33,"d") -> 12 | H33: 1.5 | I33: =+H33*G33 -> 18 | J33: =($G$17/$I$50)*I33 -> 0
... A42: 22 | B42: Vũ Thị Vân Anh | C42: NVBH | D42: 21231 | E42: 46042 | F42: 46082 | G42: =DATEDIF(E42,F42,"d") -> 40 | H42: 1 | I42: =+H42*G42 -> 40 | J42: =($G$17/$I$50)*I42 -> 0
A43: 23 | B43: Lê Thi Hương | C43: NVBH | D43: ST193 | E43: 45812 | F43: 45879 | G43: =DATEDIF(E43,F43,"d") -> 67 | H43: 1 | I43: =+H43*G43 -> 67 | J43: =($G$17/$I$50)*I43 -> 0
A44: 24 | B44: Nguyễn Thị Hồng | C44: chuyên viên | D44: ST061 | E44: 45812 | F44: 46143 | G44: =DATEDIF(E44,F44,"d") -> 331 | H44: 1.5 | I44: =+H44*G44 -> 496.5 | J44: =($G$17/$I$50)*I44 -> 0
A45: 25 | B45: Bùi Thị Mai | C45: NVBH | D45: 20552 | E45: 45812 | F45: 45872 | G45: =DATEDIF(E45,F45,"d") -> 60 | H45: 1 | I45: =+H45*G45 -> 60 | J45: =($G$17/$I$50)*I45 -> 0
A46: 26 | B46: Dương Thị Hạnh | C46: NVBH | D46: 21009 | E46: 45812 | F46: 45999 | G46: =DATEDIF(E46,F46,"d") -> 187 | H46: 1 | I46: =+H46*G46 -> 187 | J46: =($G$17/$I$50)*I46 -> 0
A47: 27 | B47: Nguyễn Trần Hoà Phương | C47: NVBH | D47: 21054 | E47: 45812 | F47: 46078 | G47: =DATEDIF(E47,F47,"d") -> 266 | H47: 1 | I47: =+H47*G47 -> 266 | J47: =($G$17/$I$50)*I47 -> 0
A48: 28 | B48: Vũ Hoàng Duy | C48: NVBH | D48: 20626 | E48: 45812 | F48: 45838 | G48: =DATEDIF(E48,F48,"d") -> 26 | H48: 1 | I48: =+H48*G48 -> 26 | J48: =($G$17/$I$50)*I48 -> 0
A49: 29 | B49: Lê Thị Bích | C49: NVBH | D49: 21215 | E49: 46006 | F49: 46103 | G49: =DATEDIF(E49,F49,"d") -> 97 | H49: 1 | I49: =+H49*G49 -> 97 | J49: =($G$17/$I$50)*I49 -> 0
A50: Tổng | G50: =+SUM(G21:G49) -> 3182 | H50: =+SUM(H21:H49) -> 33 | I50: =+SUM(I21:I49) -> 4128 | J50: =+SUM(J21:J49) -> 0
...

Sheet BBKK
K1: Mã hiệu: SBL.KDBL.QT.BM.01.02 Lần ban hành: 01 Ngày ban hành: 22/03/2018
A2: BẢNG CHÊNH LỆCH HÀNG HÓA KIỂM KÊ
K5: =SUBTOTAL(9,K9:K1480) -> 7360.0713 | L5: =SUBTOTAL(9,L9:L1480) -> 7.9129759e+08 | M5: =SUBTOTAL(9,M9:M1480) -> -6575.459 | N5: =SUBTOTAL(9,N9:N1480) -> -732309845 | O5: =+N5+L5 -> 58987748
A6: STT | B6: Loại Hàng | C6: Mã sản phẩm | D6: Mã Barcode | E6: Tên sản phẩm | F6: Giá bán lẻ | G6: Số lượng tồn phần mềm | H6: Số lượng tồn thực tế | I6: trước 13.05 | J6: kk 13.05 | K6: Chênh lệch | O6: Lý do ST giải trình | P6: Ngày điều chỉnh
K7: Chênh lệch thừa | M7: Chênh lệch thiếu
K8: Số lượng | L8: Trị giá thừa | M8: Số lượng | N8: Trị giá thiếu
B9: THỜI TRANG | C9: 142031 | D9: 2008144300011 | E9: NISHIMATSUYA- Áo Len Áo Nỉ Nhật Bản | F9: 150000 | G9: 12237 | H9: 11620 | I9: -617 | M9: =+J9+I9 -> -617 | N9: =+M9*F9 -> -92550000 | O9: Bán nhầm 142447 x617 | P9: 28/10/2025, 29/10/2025, 30/10/2025, 17/11/2025, 26/11/2025, 03/12/2025, 10/12/2025, 30/01/2026, 02/02/2026, 03/02/2026, 04/02/2026, 06/02/2026, 07/02/2026, 11/02/2026, 23/02/2026, 24/02/2026, 06/03/2026, 09/03/2026, 22/04/2026 | Q9: =VLOOKUP(D9,[1]Sheet0!$C$1:$H$65536,6,0) -> NSM MÙA ĐÔNG
B10: HỆ THỐNG | C10: 180208 | D10: 2025041800001 | E10: SKK - Túi thân thiện môi trường size nhỏ | F10: 350 | G10: 6698 | H10: 6083 | I10: -615 | M10: =+J10+I10 -> -615 | N10: =+M10*F10 -> -215250 | O10: Không rõ nguyên nhân | P10: 27/02/2026, 02/03/2026, 03/03/2026, 04/03/2026, 05/03/2026, 06/03/2026, 09/03/2026, 10/03/2026, 11/03/2026, 12/03/2026, 13/03/2026, 16/03/2026, 17/03/2026, 18/03/2026, 19/03/2026 | Q10: =VLOOKUP(D10,[1]Sheet0!$C$1:$H$65536,6,0) -> HỆ THỐNG
B11: THỜI TRANG | C11: 142450 | D11: 1414032300042 | E11: NISHIMATSUYA- Quần mùa hè trẻ em Nhật Bản | F11: 129000 | G11: 9854 | H11: 9572 | I11: -282 | M11: =+J11+I11 -> -282 | N11: =+M11*F11 -> -36378000 | O11: Bán nhầm 142446 x282 | P11: 13/06/2025, 20/06/2025, 23/06/2025, 30/06/2025, 14/07/2025, 28/07/2025, 30/07/2025, 13/08/2025, 14/08/2025, 13/10/2025, 20/10/2025, 27/10/2025 | Q11: =VLOOKUP(D11,[1]Sheet0!$C$1:$H$65536,6,0) -> NSM MÙA HÈ
B12: NGÀNH KHÁC | C12: 178736 | D12: 1722012512003 | E12: SKK- Lì xì Khai Vận | F12: 10000 | G12: 1865 | H12: 1595 | I12: -270 | M12: =+J12+I12 -> -270 | N12: =+M12*F12 -> -2700000 | O12: Không rõ nguyên nhân | P12: 28/01/2026, 29/01/2026, 30/01/2026, 02/02/2026, 03/02/2026, 04/02/2026, 06/02/2026, 24/02/2026 | Q12: =VLOOKUP(D12,[1]Sheet0!$C$1:$H$65536,6,0) -> SET QUÀ
B13: THỜI TRANG | C13: 142813 | D13: 1444042502716 | E13: NISHIMATSUYA- Váy liền thân bé gái | F13: 189000 | G13: 2192 | H13: 1952 | I13: -240 | M13: =+J13+I13 -> -240 | N13: =+M13*F13 -> -45360000 | O13: Bán nhầm 142030 x30, 142276 x3, 142454 x21, 142454 x21, 142277 x8, 142032 x2, 142281 x2, 142279 x4, 142453 x67 | P13: 10/06/2025, 08/10/2025, 14/10/2025, 15/10/2025, 16/10/2025, 17/10/2025, 20/10/2025, 21/10/2025, 22/10/2025, 20/03/2026 | Q13: =VLOOKUP(D13,[1]Sheet0!$C$1:$H$65536,6,0) -> NSM MÙA HÈ
B14: VĂN PHÒNG PHẨM | C14: 160379 | D14: 4920132010001 | E14: SKK-Hộp đựng quà 20.10 | F14: 25000 | G14: 277 | H14: 105 | I14: -172 | M14: =+J14+I14 -> -172 | N14: =+M14*F14 -> -4300000 | O14: Không rõ nguyên nhân | P14: 45950 | Q14: =VLOOKUP(D14,[1]Sheet0!$C$1:$H$65536,6,0) -> ĐỒ DÙNG VPP
B15: NGÀNH KHÁC | C15: 178708 | D15: 2025102011111 | E15: SKK- Túi quà tặng màu hồng 21*27*15cm | F15: 25000 | G15: 346 | H15: 194 | I15: -152 | M15: =+J15+I15 -> -152 | N15: =+M15*F15 -> -3800000 | O15: Không rõ nguyên nhân | P15: 13/10/2025, 05/11/2025, 17/11/2025, 26/11/2025, 21/01/2026, 22/01/2026, 03/02/2026, 07/03/2026, 09/03/2026, 12/03/2026, 16/03/2026, 17/03/2026, 26/03/2026, 14/04/2026 10:27:23 AM | Q15: =VLOOKUP(D15,[1]Sheet0!$C$1:$H$65536,6,0) -> HÀNG MARKETING
B16: NGÀNH KHÁC | C16: 178710 | D16: 2025102033333 | E16: SKK- Túi quà tặng màu xanh 21*27*15cm | F16: 25000 | G16: 517 | H16: 365 | I16: -152 | M16: =+J16+I16 -> -152 | N16: =+M16*F16 -> -3800000 | O16: Không rõ nguyên nhân | P16: 23/09/2025, 16/10/2025, 17/10/2025, 20/10/2025, 21/10/2025, 18/11/2025, 19/11/2025, 26/11/2025, 06/01/2026 4:07:21 PM, 14/01/2026, 17/01/2026, 09/03/2026, 12/03/2026, 16/03/2026, 19/03/2026, 23/03/2026 | Q16: =VLOOKUP(D16,[1]Sheet0!$C$1:$H$65536,6,0) -> HÀNG MARKETING
B17: THỰC PHẨM | C17: 153326 | D17: 8938558574044 | E17: HARU SAKURA BEEF - Thịt bò thăn ngoại Lúc lắc 200g | F17: 165000 | G17: 427 | H17: 294 | I17: -121 | J17: -12 | M17: =+J17+I17 -> -133 | N17: =+M17*F17 -> -21945000 | O17: Bán nhầm 153325 x133 | P17: 09/12/2025, 10/12/2025, 15/12/2025 3:08:37 PM, 29/12/2025 4:00:32 PM, 14/01/2026, 20/01/2026, 21/01/2026, 07/02/2026, 20/03/2026, 04/05/2026 | Q17: =VLOOKUP(D17,[1]Sheet0!$C$1:$H$65536,6,0) -> THỰC PHẨM ĐÔNG LẠNH, CHẾ BIẾN
B18: NGÀNH KHÁC | C18: 178541 | D18: DGMD10025 | E18: Đồng giá 25K | F18: 25000 | G18: 185 | H18: 85 | I18: 1 | J18: -101 | M18: =+J18+I18 -> -100 | N18: =+M18*F18 -> -2500000 | O18: Không rõ nguyên nhân | P18: 27/10/2025, 07/11/2025, 10/11/2025, 15/01/2026 | Q18: =VLOOKUP(D18,[1]Sheet0!$C$1:$H$65536,6,0) -> ĐỒNG GIÁ DATE
B19: VĂN PHÒNG PHẨM | C19: 160369 | D19: 2022087777111 | E19: SAKUKO- Túi PP dệt màu hồng size nhỏ 21x27x15cm | F19: 15000 | G19: 922 | H19: 828 | I19: -94 | M19: =+J19+I19 -> -94 | N19: =+M19*F19 -> -1410000 | O19: Không rõ nguyên nhân | P19: 20/06/2025, 21/07/2025, 28/07/2025, 14/10/2025, 21/10/2025, 24/11/2025, 16/03/2026, 17/03/2026, 23/03/2026, 24/03/2026, 27/03/2026, 30/03/2026, 31/03/2026, 02/04/2026, 06/04/2026 8:51:40 AM, 07/04/2026 10:37:54 AM, 09/04/2026, 10/04/2026 10:54:24 AM, 13/04/2026 8:54:09 AM, 04/05/2026 | Q19: =VLOOKUP(D19,[1]Sheet0!$C$1:$H$65536,6,0) -> ĐỒ DÙNG VPP
B20: THỰC PHẨM | C20: 154453 | D20: 4901830356106 | E20: D'ASSES- Bánh quy nhân socola matcha 12 chiếc | F20: 67000 | G20: 212 | H20: 127 | I20: -63 | J20: -22 | M20: =+J20+I20 -> -85 | N20: =+M20*F20 -> -5695000 | O20: Bán nhầm 154455 x85 | P20: 05/01/2026 3:51:24 PM, 22/01/2026, 24/02/2026, 30/03/2026 | Q20: =VLOOKUP(D20,[1]Sheet0!$C$1:$H$65536,6,0) -> BÁNH KẸO, ĐỒ ĂN VẶT
B21: NGÀNH KHÁC | C21: 178741 | D21: 1722012512058 | E21: SKK- Túi quà Tết Chiêu Tài (Đỏ L) | F21: 20000 | G21: 363 | H21: 280 | I21: -83 | M21: =+J21+I21 -> -83 | N21: =+M21*F21 -> -1660000 | O21: Bán nhầm 178740 x79, 178676 x4 | P21: 09/01/2026 3:04:24 PM, 09/02/2026, 05/03/2026, 09/03/2026, 03/04/2026, 14/04/2026 10:27:23 AM | Q21: =VLOOKUP(D21,[1]Sheet0!$C$1:$H$65536,6,0) -> SET QUÀ
B22: VĂN PHÒNG PHẨM | C22: 160377 | D22: 4945202320101 | E22: SKK-Túi quà size nhỏ 20x12,5x10 cm | F22: 12000 | G22: 238 | H22: 162 | I22: -76 | M22: =+J22+I22 -> -76 | N22: =+M22*F22 -> -912000 | O22: Không rõ nguyên nhân | P22: 15/01/2026, 16/01/2026, 07/02/2026, 23/02/2026, 02/03/2026, 03/03/2026, 04/03/2026, 09/03/2026, 20/04/2026, 22/04/2026 | Q22: =VLOOKUP(D22,[1]Sheet0!$C$1:$H$65536,6,0) -> ĐỒ DÙNG VPP
B23: NGÀNH KHÁC | C23: 178738 | D23: 1722012512027 | E23: SKK- Lì xì Vinh Hoa | F23: 10000 | G23: 535 | H23: 459 | I23: -76 | M23: =+J23+I23 -> -76 | N23: =+M23*F23 -> -760000 | O23: Bán nhầm 178641 x76 | P23: 23/01/2026, 07/02/2026, 09/02/2026, 24/02/2026, 04/03/2026, 05/03/2026 | Q23: =VLOOKUP(D23,[1]Sheet0!$C$1:$H$65536,6,0) -> SET QUÀ
B24: VĂN PHÒNG PHẨM | C24: 160337 | D24: 2021555555555 | E24: Sakuko - Lì xì Tết Bình An | F24: 10000 | G24: 75 | H24: 0 | I24: -75 | M24: =+J24+I24 -> -75 | N24: =+M24*F24 -> -750000 | O24: Không rõ nguyên nhân | P24: 46077 | Q24: =VLOOKUP(D24,[1]Sheet0!$C$1:$H$65536,6,0) -> ĐỒ DÙNG VPP
B25: NGÀNH KHÁC | C25: 178586 | D25: DGMD10080N | E25: Đồng giá 80K | F25: 80000 | G25: 112 | H25: 39 | I25: -57 | J25: -16 | M25: =+J25+I25 -> -73 | N25: =+M25*F25 -> -5840000 | O25: Không rõ nguyên nhân | P25: 28/07/2025, 11/08/2025, 25/08/2025, 23/02/2026 | Q25: =VLOOKUP(D25,[1]Sheet0!$C$1:$H$65536,6,0) -> #N/A
B26: NGÀNH KHÁC | C26: 178548 | D26: DGMD10030 | E26: Đồng giá 30K | F26: 30000 | G26: 345 | H26: 273 | I26: -8 | J26: -64 | M26: =+J26+I26 -> -72 | N26: =+M26*F26 -> -2160000 | O26: Không rõ nguyên nhân | P26: 07/11/2025, 03/12/2025, 04/12/2025, 23/02/2026, 06/04/2026 8:51:40 AM | Q26: =VLOOKUP(D26,[1]Sheet0!$C$1:$H$65536,6,0) -> ĐỒNG GIÁ DATE
B27: NGÀNH KHÁC | C27: 178717 | D27: 1611022111020 | E27: SAKUKO- Túi quà sinh nhật 21*27*10cm | F27: 15000 | G27: 238 | H27: 166 | I27: -72 | M27: =+J27+I27 -> -72 | N27: =+M27*F27 -> -1080000 | O27: Không rõ nguyên nhân | P27: 03/11/2025, 05/11/2025, 17/11/2025, 18/11/2025, 19/11/2025, 21/11/2025, 17/01/2026, 23/03/2026, 24/03/2026, 04/05/2026 | Q27: =VLOOKUP(D27,[1]Sheet0!$C$1:$H$65536,6,0) -> HÀNG MARKETING
B28: THỰC PHẨM | C28: 152844 | D28: 4901005501515 | E28: GLICO- Bánh socola nhân kem trà xanh 6 chiếc | F28: 95000 | G28: 305 | H28: 238 | I28: -44 | J28: -23 | M28: =+J28+I28 -> -67 | N28: =+M28*F28 -> -6365000 | O28: Không rõ nguyên nhân | P28: 17/01/2026, 21/01/2026, 22/01/2026, 23/01/2026 | Q28: =VLOOKUP(D28,[1]Sheet0!$C$1:$H$65536,6,0) -> BÁNH KẸO, ĐỒ ĂN VẶT
B29: THỜI TRANG | C29: 142036 | D29: 2008144300066 | E29: NISHIMATSUYA- Bộ Đồ Body Liền Thân Trẻ em Nhật Bản | F29: 160000 | G29: 547 | H29: 484 | I29: -63 | M29: =+J29+I29 -> -63 | N29: =+M29*F29 -> -10080000 | O29: Bán nhầm 142452 x63 | P29: 15/10/2025, 23/12/2025 3:28:13 PM, 24/12/2025 2:37:59 PM, 25/12/2025 3:20:39 PM, 29/12/2025 4:00:32 PM, 05/01/2026 3:51:24 PM, 06/01/2026 4:07:21 PM, 08/01/2026 10:07:08 AM, 13/01/2026, 27/01/2026, 03/02/2026, 09/02/2026, 26/02/2026, 20/03/2026, 25/03/2026, 06/04/2026 8:51:40 AM | Q29: =VLOOKUP(D29,[1]Sheet0!$C$1:$H$65536,6,0) -> NSM MÙA ĐÔNG
B30: THỜI TRANG | C30: 142814 | D30: 1444082502271 | E30: NISHIMATSUYA- Bộ đồ liền thân trẻ em | F30: 159000 | G30: 91 | H30: 38 | I30: -53 | M30: =+J30+I30 -> -53 | N30: =+M30*F30 -> -8427000 | O30: Bán nhầm 142452 x53 | P30: 08/09/2025, 09/10/2025, 27/03/2026 | Q30: =VLOOKUP(D30,[1]Sheet0!$C$1:$H$65536,6,0) -> NSM MÙA HÈ
B31: VĂN PHÒNG PHẨM | C31: 160370 | D31: 2022086666111 | E31: SAKUKO- Túi PP dệt màu xanh size to 42x35x16cm | F31: 30000 | G31: 315 | H31: 263 | I31: -52 | M31: =+J31+I31 -> -52 | N31: =+M31*F31 -> -1560000 | O31: Không rõ nguyên nhân | P31: 07/06/2025, 24/02/2026, 23/03/2026, 26/03/2026, 27/03/2026, 30/03/2026, 02/04/2026, 06/04/2026 8:51:40 AM, 07/04/2026 10:37:54 AM, 09/04/2026, 10/04/2026 10:54:24 AM, 13/04/2026 8:54:09 AM, 04/05/2026 | Q31: =VLOOKUP(D31,[1]Sheet0!$C$1:$H$65536,6,0) -> ĐỒ DÙNG VPP
B32: NGÀNH KHÁC | C32: 178544 | D32: DGMD10050 | E32: Đồng giá 50K | F32: 50000 | G32: 815 | H32: 766 | I32: -55 | J32: 6 | M32: =+J32+I32 -> -49 | N32: =+M32*F32 -> -2450000 | O32: Không rõ nguyên nhân | P32: 02/07/2025, 03/07/2025, 04/07/2025, 07/07/2025, 11/07/2025, 30/09/2025, 06/10/2025, 23/10/2025, 24/10/2025, 24/11/2025, 03/12/2025, 09/12/2025, 11/12/2025, 15/12/2025 3:08:37 PM, 13/01/2026, 21/01/2026, 27/01/2026, 23/02/2026, 23/03/2026, 25/03/2026, 26/03/2026, 31/03/2026, 05/05/2026, 11/05/2026 | Q32: =VLOOKUP(D32,[1]Sheet0!$C$1:$H$65536,6,0) -> ĐỒNG GIÁ DATE
B33: NGÀNH KHÁC | C33: 178739 | D33: 1722012512034 | E33: SKK- Lì xì Trường Cát | F33: 10000 | G33: 99 | H33: 51 | I33: -48 | M33: =+J33+I33 -> -48 | N33: =+M33*F33 -> -480000 | O33: Bán nhầm 178641 x43 | P33: 27/01/2026, 24/02/2026 | Q33: =VLOOKUP(D33,[1]Sheet0!$C$1:$H$65536,6,0) -> SET QUÀ
B34: THỰC PHẨM | C34: 154454 | D34: 4901830351873 | E34: D'ASSES- Bánh quy nhân socola socola 12 chiếc | F34: 67000 | G34: 580 | H34: 533 | I34: -66 | J34: 19 | M34: =+J34+I34 -> -47 | N34: =+M34*F34 -> -3149000 | O34: Không rõ nguyên nhân | P34: 27/01/2026, 30/01/2026, 02/02/2026, 30/03/2026 | Q34: =VLOOKUP(D34,[1]Sheet0!$C$1:$H$65536,6,0) -> BÁNH KẸO, ĐỒ ĂN VẶT
B35: THỜI TRANG | C35: 142278 | D35: 1444042204016 | E35: NISHIMATSUYA- Quần thu đông trẻ em | F35: 105000 | G35: 335 | H35: 289 | I35: -6 | J35: -40 | M35: =+J35+I35 -> -46 | N35: =+M35*F35 -> -4830000 | O35: Bán nhầm 142446 x46 | P35: 45957 | Q35: =VLOOKUP(D35,[1]Sheet0!$C$1:$H$65536,6,0) -> NSM MÙA ĐÔNG
B36: NHÀ CỬA ĐỜI SỐNG | C36: 133658 | D36: 4901121181431 | E36: NEPIA- Set hộp giấy ăn hình hoa (300 tờ x 5 hộp) | F36: 120000 | G36: 257 | H36: 213 | I36: -44 | M36: =+J36+I36 -> -44 | N36: =+M36*F36 -> -5280000 | O36: Bán nhầm 134475 x44 | P36: 10/06/2025, 12/06/2025, 13/06/2025, 16/06/2025, 17/06/2025, 18/06/2025, 20/06/2025, 02/07/2025, 21/07/2025 | Q36: =VLOOKUP(D36,[1]Sheet0!$C$1:$H$65536,6,0) -> SẢN PHẨM TỪ GIẤY
B37: NGÀNH KHÁC | C37: 178547 | D37: DGMD10040 | E37: Đồng giá 40K | F37: 40000 | G37: 237 | H37: 198 | I37: -7 | J37: -32 | M37: =+J37+I37 -> -39 | N37: =+M37*F37 -> -1560000 | O37: Không rõ nguyên nhân | P37: 13/06/2025, 30/06/2025, 07/07/2025, 14/07/2025, 28/07/2025, 15/09/2025, 22/09/2025, 23/09/2025, 30/09/2025, 06/10/2025, 23/10/2025, 24/10/2025, 04/12/2025, 09/12/2025 | Q37: =VLOOKUP(D37,[1]Sheet0!$C$1:$H$65536,6,0) -> ĐỒNG GIÁ DATE
B38: THỰC PHẨM | C38: 154456 | D38: 8938558574495 | E38: HARU SAKURA BEEF - Thịt bò thăn ngoại Bít tết 150g | F38: 135000 | G38: 1431 | H38: 1396 | I38: -10 | J38: -25 | M38: =+J38+I38 -> -35 | N38: =+M38*F38 -> -4725000 | O38: Không rõ nguyên nhân | P38: 29/01/2026, 09/02/2026, 11/02/2026, 23/02/2026, 19/03/2026 | Q38: =VLOOKUP(D38,[1]Sheet0!$C$1:$H$65536,6,0) -> THỰC PHẨM ĐÔNG LẠNH, CHẾ BIẾN
B39: THỰC PHẨM | C39: 154464 | D39: 4909466001377 | E39: SHOHO SEIKA- Bánh mochi nhân socola 10 chiếc | F39: 115000 | G39: 34 | H39: 0 | I39: -34 | M39: =+J39+I39 -> -34 | N39: =+M39*F39 -> -3910000 | O39: Không rõ nguyên nhân | P39: 14/01/2026, 29/01/2026 | Q39: =VLOOKUP(D39,[1]Sheet0!$C$1:$H$65536,6,0) -> BÁNH KẸO, ĐỒ ĂN VẶT
B40: THỰC PHẨM | C40: 154279 | D40: 8938558574464 | E40: SANGEN WAGYU- Thịt bò tam vương bít tết 200g | F40: 145000 | G40: 51 | H40: 18 | I40: -17 | J40: -16 | M40: =+J40+I40 -> -33 | N40: =+M40*F40 -> -4785000 | O40: Bán nhầm 153325 x31, 153269 x2 | P40: 46051 | Q40: =VLOOKUP(D40,[1]Sheet0!$C$1:$H$65536,6,0) -> THỰC PHẨM ĐÔNG LẠNH, CHẾ BIẾN
B41: NGÀNH KHÁC | C41: 178564 | D41: DGMH20000 | E41: Đồng giá 20.000 | F41: 20000 | G41: 233 | H41: 200 | I41: -3 | J41: -30 | M41: =+J41+I41 -> -33 | N41: =+M41*F41 -> -660000 | O41: Không rõ nguyên nhân | P41: 05/12/2025, 23/02/2026 | Q41: =VLOOKUP(D41,[1]Sheet0!$C$1:$H$65536,6,0) -> ĐỒNG GIÁ MUA HÀNG
B42: NHÀ CỬA ĐỜI SỐNG | C42: 174470 | D42: 4903367301956 | E42: ROCKET- Rửa chén hương táo 600ml | F42: 40000 | G42: 200 | H42: 169 | I42: -31 | M42: =+J42+I42 -> -31 | N42: =+M42*F42 -> -1240000 | O42: Bán nhầm 134088 x26, 174522 x5 | P42: 11/08/2025, 11/09/2025, 21/11/2025, 26/11/2025, 01/12/2025, 04/12/2025, 10/12/2025, 25/03/2026, 27/03/2026, 30/03/2026, 03/04/2026, 04/04/2026, 06/04/2026 8:51:40 AM | Q42: =VLOOKUP(D42,[1]Sheet0!$C$1:$H$65536,6,0) -> XÀ PHÒNG, CHẤT TẨY RỬA
...

Sheet Sheet1
A1: Ngành | B1: Mã hàng | C1: Barcode | D1: Tên SP | E1: Giá | F1: Mã hàng | G1: Ngành | H1: Nhóm | I1: Loại | J1: date | S1: Tên SP | T1: Giá | U1: Mã hàng | V1: Ngành | W1: Nhóm | X1: Loại
A2: CHĂM SÓC SẮC ĐẸP | B2: 100020 | C2: 4971710311587 | D2: KOSE- Sữa tắm Softymo White Body Soap chống lão hóa Ha (600ml) | E2: 259000 | F2: 49 | G2: 54 | I2: 5 | J2: 23/03/2026, 24/03/2026, 28/04/2026 | K2: =B2 -> 100020 | L2: =A2 -> CHĂM SÓC SẮC ĐẸP | P2: =VLOOKUP(Q2,K:L,2,0) -> CHĂM SÓC SẮC ĐẸP | Q2: =VLOOKUP(R2,C:K,9,0) -> 100020 | R2: 4971710311587 | S2: =VLOOKUP(R2,C:D,2,0) -> KOSE- Sữa tắm Softymo White Body Soap chống lão hóa Ha (600ml) | T2: =VLOOKUP(R2,C:E,3,0) -> 259000 | U2: 171 | V2: 173 | W2: -3 | X2: 5 | Y2: =+X2+W2 -> 2 | Z2: =+Y2*T2 -> 518000 | AA2: 23/03/2026, 24/03/2026, 28/04/2026
A3: CHĂM SÓC SẮC ĐẸP | B3: 100020 | C3: 4971710311587 | D3: KOSE- Sữa tắm Softymo White Body Soap chống lão hóa Ha (600ml) | E3: 259000 | F3: 68 | G3: 67 | H3: -1 | J3: 23/03/2026, 24/03/2026, 28/04/2026 | K3: =B3 -> 100020 | L3: =A3 -> CHĂM SÓC SẮC ĐẸP | P3: =VLOOKUP(Q3,K:L,2,0) -> CHĂM SÓC SẮC ĐẸP | Q3: =VLOOKUP(R3,C:K,9,0) -> 100187 | R3: 4511413302163 | S3: =VLOOKUP(R3,C:D,2,0) -> DHC-Son dưỡng Lip Cream không màu 1.5g | T3: =VLOOKUP(R3,C:E,3,0) -> 199000 | U3: -35 | V3: 1 | W3: 36 | Y3: =+X3+W3 -> 36 | Z3: =+Y3*T3 -> 7164000 | AA3: 18/12/2025, 22/12/2025 11:13:54 AM, 23/12/2025 3:28:13 PM, 27/01/2026, 29/01/2026, 30/01/2026, 07/02/2026, 09/02/2026, 24/02/2026, 25/02/2026, 09/03/2026, 16/03/2026
A4: CHĂM SÓC SẮC ĐẸP | B4: 100020 | C4: 4971710311587 | D4: KOSE- Sữa tắm Softymo White Body Soap chống lão hóa Ha (600ml) | E4: 259000 | F4: 1 | G4: 0 | H4: -1 | J4: 23/03/2026, 24/03/2026, 28/04/2026 | K4: =B4 -> 100020 | L4: =A4 -> CHĂM SÓC SẮC ĐẸP | P4: =VLOOKUP(Q4,K:L,2,0) -> CHĂM SÓC SẮC ĐẸP | Q4: =VLOOKUP(R4,C:K,9,0) -> 100205 | R4: 4956962108017 | S4: =VLOOKUP(R4,C:D,2,0) -> ALOINS- Kem dưỡng da toàn thân Aloins Cream 185g | T4: =VLOOKUP(R4,C:E,3,0) -> 350000 | U4: 62 | V4: 61 | W4: -3 | X4: 2 | Y4: =+X4+W4 -> -1 | Z4: =+Y4*T4 -> -350000 | AA4: 27/03/2026, 30/03/2026
A5: CHĂM SÓC SẮC ĐẸP | B5: 100020 | C5: 4971710311587 | D5: KOSE- Sữa tắm Softymo White Body Soap chống lão hóa Ha (600ml) | E5: 259000 | F5: 53 | G5: 52 | H5: -1 | J5: 23/03/2026, 24/03/2026, 28/04/2026 | K5: =B5 -> 100020 | L5: =A5 -> CHĂM SÓC SẮC ĐẸP | P5: =VLOOKUP(Q5,K:L,2,0) -> CHĂM SÓC SẮC ĐẸP | Q5: =VLOOKUP(R5,C:K,9,0) -> 100423 | R5: 4901872441587 | S5: =VLOOKUP(R5,C:D,2,0) -> SHISEIDO- Sữa tắm Perfect Bubble hương hoa tự nhiên 500ml (xanh) | T5: =VLOOKUP(R5,C:E,3,0) -> 217000 | U5: 23 | V5: 11 | W5: -8 | X5: -4 | Y5: =+X5+W5 -> -12 | Z5: =+Y5*T5 -> -2604000 | AA5: 18/12/2025, 25/12/2025 3:20:39 PM, 08/01/2026 10:07:08 AM, 07/02/2026, 23/02/2026
A6: CHĂM SÓC SẮC ĐẸP | B6: 100187 | C6: 4511413302163 | D6: DHC-Son dưỡng Lip Cream không màu 1.5g | E6: 199000 | F6: -8 | G6: 0 | H6: 8 | J6: 18/12/2025, 22/12/2025 11:13:54 AM, 23/12/2025 3:28:13 PM, 27/01/2026, 29/01/2026, 30/01/2026, 07/02/2026, 09/02/2026, 24/02/2026, 25/02/2026, 09/03/2026, 16/03/2026 | K6: =B6 -> 100187 | L6: =A6 -> CHĂM SÓC SẮC ĐẸP | P6: =VLOOKUP(Q6,K:L,2,0) -> CHĂM SÓC SẮC ĐẸP | Q6: =VLOOKUP(R6,C:K,9,0) -> 100847 | R6: 4901872443758 | S6: =VLOOKUP(R6,C:D,2,0) -> SHISEIDO- Sữa tắm Bubble Sweet floral 500ml | T6: =VLOOKUP(R6,C:E,3,0) -> 217000 | U6: 41 | V6: 29 | W6: -5 | X6: -7 | Y6: =+X6+W6 -> -12 | Z6: =+Y6*T6 -> -2604000 | AA6: 03/02/2026, 20/04/2026, 22/04/2026, 28/04/2026, 04/05/2026
A7: CHĂM SÓC SẮC ĐẸP | B7: 100187 | C7: 4511413302163 | D7: DHC-Son dưỡng Lip Cream không màu 1.5g | E7: 199000 | F7: -9 | G7: 0 | H7: 9 | J7: 18/12/2025, 22/12/2025 11:13:54 AM, 23/12/2025 3:28:13 PM, 27/01/2026, 29/01/2026, 30/01/2026, 07/02/2026, 09/02/2026, 24/02/2026, 25/02/2026, 09/03/2026, 16/03/2026 | K7: =B7 -> 100187 | L7: =A7 -> CHĂM SÓC SẮC ĐẸP | P7: =VLOOKUP(Q7,K:L,2,0) -> CHĂM SÓC SẮC ĐẸP | Q7: =VLOOKUP(R7,C:K,9,0) -> 100894 | R7: 4531261702458 | S7: =VLOOKUP(R7,C:D,2,0) -> COTTON LABO- Giấy thấm dầu 120 tờ | T7: =VLOOKUP(R7,C:E,3,0) -> 90000 | U7: -2 | V7: 0 | W7: 2 | Y7: =+X7+W7 -> 2 | Z7: =+Y7*T7 -> 180000 | AA7: 09/02/2026, 09/03/2026
A8: CHĂM SÓC SẮC ĐẸP | B8: 100187 | C8: 4511413302163 | D8: DHC-Son dưỡng Lip Cream không màu 1.5g | E8: 199000 | F8: -3 | G8: 0 | H8: 3 | J8: 18/12/2025, 22/12/2025 11:13:54 AM, 23/12/2025 3:28:13 PM, 27/01/2026, 29/01/2026, 30/01/2026, 07/02/2026, 09/02/2026, 24/02/2026, 25/02/2026, 09/03/2026, 16/03/2026 | K8: =B8 -> 100187 | L8: =A8 -> CHĂM SÓC SẮC ĐẸP | P8: =VLOOKUP(Q8,K:L,2,0) -> CHĂM SÓC HÀNG NGÀY | Q8: =VLOOKUP(R8,C:K,9,0) -> 101007 | R8: 4538604150020 | S8: =VLOOKUP(R8,C:D,2,0) -> UFC- Bàn chải Dent Ultima TL-S 1 loại mềm | T8: =VLOOKUP(R8,C:E,3,0) -> 58000 | U8: -5 | V8: 0 | W8: 5 | Y8: =+X8+W8 -> 5 | Z8: =+Y8*T8 -> 290000 | AA8: 03/11/2025, 05/11/2025
A9: CHĂM SÓC SẮC ĐẸP | B9: 100187 | C9: 4511413302163 | D9: DHC-Son dưỡng Lip Cream không màu 1.5g | E9: 199000 | F9: -2 | G9: 0 | H9: 2 | J9: 18/12/2025, 22/12/2025 11:13:54 AM, 23/12/2025 3:28:13 PM, 27/01/2026, 29/01/2026, 30/01/2026, 07/02/2026, 09/02/2026, 24/02/2026, 25/02/2026, 09/03/2026, 16/03/2026 | K9: =B9 -> 100187 | L9: =A9 -> CHĂM SÓC SẮC ĐẸP | P9: =VLOOKUP(Q9,K:L,2,0) -> CHĂM SÓC SẮC ĐẸP | Q9: =VLOOKUP(R9,C:K,9,0) -> 101352 | R9: 4513574027077 | S9: =VLOOKUP(R9,C:D,2,0) -> HATOMUGI- Sữa tắm trắng da ý dĩ 800ml | T9: =VLOOKUP(R9,C:E,3,0) -> 180000 | U9: 85 | V9: 100 | W9: 7 | X9: 8 | Y9: =+X9+W9 -> 15 | Z9: =+Y9*T9 -> 2700000 | AA9: 29/01/2026, 30/01/2026, 02/02/2026, 06/02/2026, 09/03/2026
A10: CHĂM SÓC SẮC ĐẸP | B10: 100187 | C10: 4511413302163 | D10: DHC-Son dưỡng Lip Cream không màu 1.5g | E10: 199000 | F10: -2 | G10: 0 | H10: 2 | J10: 18/12/2025, 22/12/2025 11:13:54 AM, 23/12/2025 3:28:13 PM, 27/01/2026, 29/01/2026, 30/01/2026, 07/02/2026, 09/02/2026, 24/02/2026, 25/02/2026, 09/03/2026, 16/03/2026 | K10: =B10 -> 100187 | L10: =A10 -> CHĂM SÓC SẮC ĐẸP | P10: =VLOOKUP(Q10,K:L,2,0) -> CHĂM SÓC SẮC ĐẸP | Q10: =VLOOKUP(R10,C:K,9,0) -> 101369 | R10: 4901872958238 | S10: =VLOOKUP(R10,C:D,2,0) -> SHISEIDO- Kem dưỡng chống lão hóa Aqualabel 5in1 - 90G | T10: =VLOOKUP(R10,C:E,3,0) -> 480000 | U10: -4 | V10: 0 | W10: 4 | Y10: =+X10+W10 -> 4 | Z10: =+Y10*T10 -> 1920000 | AA10: 24/02/2026, 27/02/2026, 09/03/2026, 10/03/2026
A11: CHĂM SÓC SẮC ĐẸP | B11: 100187 | C11: 4511413302163 | D11: DHC-Son dưỡng Lip Cream không màu 1.5g | E11: 199000 | F11: -2 | G11: 0 | H11: 2 | J11: 18/12/2025, 22/12/2025 11:13:54 AM, 23/12/2025 3:28:13 PM, 27/01/2026, 29/01/2026, 30/01/2026, 07/02/2026, 09/02/2026, 24/02/2026, 25/02/2026, 09/03/2026, 16/03/2026 | K11: =B11 -> 100187 | L11: =A11 -> CHĂM SÓC SẮC ĐẸP | P11: =VLOOKUP(Q11,K:L,2,0) -> CHĂM SÓC SẮC ĐẸP | Q11: =VLOOKUP(R11,C:K,9,0) -> 101379 | R11: 4971710383904 | S11: =VLOOKUP(R11,C:D,2,0) -> KOSE- Kem Tay Q10 dưỡng trắng hương đào 80g | T11: =VLOOKUP(R11,C:E,3,0) -> 170000 | U11: -3 | V11: 0 | W11: 3 | Y11: =+X11+W11 -> 3 | Z11: =+Y11*T11 -> 510000 | AA11: 24/02/2026, 12/03/2026
A12: CHĂM SÓC SẮC ĐẸP | B12: 100187 | C12: 4511413302163 | D12: DHC-Son dưỡng Lip Cream không màu 1.5g | E12: 199000 | F12: -3 | G12: 0 | H12: 3 | J12: 18/12/2025, 22/12/2025 11:13:54 AM, 23/12/2025 3:28:13 PM, 27/01/2026, 29/01/2026, 30/01/2026, 07/02/2026, 09/02/2026, 24/02/2026, 25/02/2026, 09/03/2026, 16/03/2026 | K12: =B12 -> 100187 | L12: =A12 -> CHĂM SÓC SẮC ĐẸP | P12: =VLOOKUP(Q12,K:L,2,0) -> CHĂM SÓC SẮC ĐẸP | Q12: =VLOOKUP(R12,C:K,9,0) -> 101445 | R12: 4902468232008 | S12: =VLOOKUP(R12,C:D,2,0) -> MEISHOKU- Kem BB trang điểm- tone da trắng | T12: =VLOOKUP(R12,C:E,3,0) -> 345000 | U12: 19 | V12: 18 | W12: 1 | X12: -2 | Y12: =+X12+W12 -> -1 | Z12: =+Y12*T12 -> -345000 | AA12: 09/12/2025, 11/12/2025
A13: CHĂM SÓC SẮC ĐẸP | B13: 100187 | C13: 4511413302163 | D13: DHC-Son dưỡng Lip Cream không màu 1.5g | E13: 199000 | F13: -1 | G13: 0 | H13: 1 | J13: 18/12/2025, 22/12/2025 11:13:54 AM, 23/12/2025 3:28:13 PM, 27/01/2026, 29/01/2026, 30/01/2026, 07/02/2026, 09/02/2026, 24/02/2026, 25/02/2026, 09/03/2026, 16/03/2026 | K13: =B13 -> 100187 | L13: =A13 -> CHĂM SÓC SẮC ĐẸP | P13: =VLOOKUP(Q13,K:L,2,0) -> CHĂM SÓC SẮC ĐẸP | Q13: =VLOOKUP(R13,C:K,9,0) -> 101561 | R13: 4987205080302 | S13: =VLOOKUP(R13,C:D,2,0) -> HOYU-Thuốc nhuộm bạc Bigen dạng kem-hạt dẻ 3G | T13: =VLOOKUP(R13,C:E,3,0) -> 195000 | U13: 11 | V13: 20 | W13: -1 | X13: 10 | Y13: =+X13+W13 -> 9 | Z13: =+Y13*T13 -> 1755000 | AA13: 46079
A14: CHĂM SÓC SẮC ĐẸP | B14: 100205 | C14: 4956962108017 | D14: ALOINS- Kem dưỡng da toàn thân Aloins Cream 185g | E14: 350000 | F14: 28 | G14: 30 | I14: 2 | J14: 27/03/2026, 30/03/2026 | K14: =B14 -> 100205 | L14: =A14 -> CHĂM SÓC SẮC ĐẸP | P14: =VLOOKUP(Q14,K:L,2,0) -> CHĂM SÓC SẮC ĐẸP | Q14: =VLOOKUP(R14,C:K,9,0) -> 101562 | R14: 4987205080609 | S14: =VLOOKUP(R14,C:D,2,0) -> HOYU-Thuốc nhuộm bạc Bigen dạng kem-nâuNatural 6G | T14: =VLOOKUP(R14,C:E,3,0) -> 195000 | U14: 24 | V14: 14 | W14: -10 | Y14: =+X14+W14 -> -10 | Z14: =+Y14*T14 -> -1950000 | AA14: 10/12/2025, 15/12/2025 3:08:37 PM
A15: CHĂM SÓC SẮC ĐẸP | B15: 100205 | C15: 4956962108017 | D15: ALOINS- Kem dưỡng da toàn thân Aloins Cream 185g | E15: 350000 | F15: 1 | G15: 0 | H15: -1 | J15: 27/03/2026, 30/03/2026 | K15: =B15 -> 100205 | L15: =A15 -> CHĂM SÓC SẮC ĐẸP | P15: =VLOOKUP(Q15,K:L,2,0) -> CHĂM SÓC SẮC ĐẸP | Q15: =VLOOKUP(R15,C:K,9,0) -> 101563 | R15: 4987205080500 | S15: =VLOOKUP(R15,C:D,2,0) -> HOYU-Thuốc nhuộm bạc Bigen dạng kem-hạt dẻ đậm 5G | T15: =VLOOKUP(R15,C:E,3,0) -> 195000 | U15: -13 | V15: 0 | W15: 13 | Y15: =+X15+W15 -> 13 | Z15: =+Y15*T15 -> 2535000 | AA15: 10/12/2025, 15/12/2025 3:08:37 PM, 24/02/2026, 26/02/2026
A16: CHĂM SÓC SẮC ĐẸP | B16: 100205 | C16: 4956962108017 | D16: ALOINS- Kem dưỡng da toàn thân Aloins Cream 185g | E16: 350000 | F16: 33 | G16: 31 | H16: -2 | J16: 27/03/2026, 30/03/2026 | K16: =B16 -> 100205 | L16: =A16 -> CHĂM SÓC SẮC ĐẸP | P16: =VLOOKUP(Q16,K:L,2,0) -> CHĂM SÓC SẮC ĐẸP | Q16: =VLOOKUP(R16,C:K,9,0) -> 101614 | R16: 4513574031319 | S16: =VLOOKUP(R16,C:D,2,0) -> HATOMUGI- Xịt khoáng ý dĩ dưỡng ẩm 250ml | T16: =VLOOKUP(R16,C:E,3,0) -> 145000 | U16: 28 | V16: 21 | W16: -9 | X16: 2 | Y16: =+X16+W16 -> -7 | Z16: =+Y16*T16 -> -1015000 | AA16: 01/04/2026, 07/04/2026 10:37:54 AM, 28/04/2026, 04/05/2026
